<?xml version="1.0" ?>
<!-- =================================================================================== -->
<!-- |    This document was autogenerated by xacro from /home/rsinnet/proj/ros_ws/grillbot_ws/src/grillbot/miso_description/urdf/fanuc_lrmate200id_7lc.urdf.xacro | -->
<!-- |    EDITING THIS FILE BY HAND IS NOT RECOMMENDED                                 | -->
<!-- =================================================================================== -->
<robot  name="LR">
  <link
    name="base_link">
    <inertial>
      <origin
        xyz="-0.00682671411672755 -0.000321709618740103 0.0804229487704526"
        rpy="0 0 0" />
      <mass
        value="4.85330591768596E-10" />
      <inertia
        ixx="2.19871507297146E-12"
        ixy="-1.18498593686301E-14"
        ixz="1.43011350502118E-14"
        iyy="2.38291565775529E-12"
        iyz="-3.06011987189728E-15"
        izz="2.28014946221614E-12" />
    </inertial>
    <visual>
      <origin
        xyz="0 0 0"
        rpy="0 0 0" />
      <geometry>
        <mesh
          filename="package://LR Mate-200iD7LC_v3/meshes/base_link.stl" />
      </geometry>
      <material
        name="material">
        <color
          rgba="1 1 1 1" />
      </material>
    </visual>
    <collision>
      <origin
        xyz="0 0 0"
        rpy="0 0 0" />
      <geometry>
        <mesh
          filename="package://LR Mate-200iD7LC_v3/meshes/base_link.stl" />
      </geometry>
    </collision>
  </link>
  <joint
    name="joint_1"
    type="revolute">
    <origin
      xyz="0 0 0.169"
      rpy="0 0 0" />
    <parent
      link="base_link" />
    <child
      link="link_1" />
    <axis
      xyz="0 0 1" />
  </joint>
  <link
    name="link_1">
    <inertial>
      <origin
        xyz="5.6114E-13 1.423E-12 -0.169"
        rpy="0 0 0" />
      <mass
        value="4.85330591768596E-4" />
      <inertia
        ixx="0"
        ixy="0"
        ixz="0"
        iyy="0"
        iyz="0"
        izz="0" />
    </inertial>
    <visual>
      <origin
        xyz="0 0 0"
        rpy="0 0 0" />
      <geometry>
        <mesh
          filename="package://LR Mate-200iD7LC_v3/meshes/link_1.stl" />
      </geometry>
      <material
        name="material">
        <color
          rgba="1 1 1 1" />
      </material>
    </visual>
    <collision>
      <origin
        xyz="0 0 0"
        rpy="0 0 0" />
      <geometry>
        <mesh
          filename="package://LR Mate-200iD7LC_v3/meshes/link_1.stl" />
      </geometry>
    </collision>
  </link>
  <joint
    name="joint_2"
    type="revolute">
    <origin
      xyz="0.0500000000005612 0.00100000000142298 0.1601"
      rpy="-1.5707963267949 0 0" />
    <parent
      link="link_1" />
    <child
      link="link_2" />
    <axis
      xyz="0 0 1" />
  </joint>
  <link
    name="link_2">
    <inertial>
      <origin
        xyz="-0.00966840230594466 -0.175561605182666 -0.00154756288856032"
        rpy="0 0 0" />
      <mass
        value="7.96645798047262E-10" />
      <inertia
        ixx="1.95696979665405E-11"
        ixy="-2.72595910426984E-13"
        ixz="9.5863153169622E-15"
        iyy="3.58221345125E-12"
        iyz="8.84587811572339E-14"
        izz="1.74744250589923E-11" />
    </inertial>
    <visual>
      <origin
        xyz="0 0 0"
        rpy="0 0 0" />
      <geometry>
        <mesh
          filename="package://LR Mate-200iD7LC_v3/meshes/link_2.stl" />
      </geometry>
      <material
        name="material">
        <color
          rgba="1 1 1 1" />
      </material>
    </visual>
    <collision>
      <origin
        xyz="0 0 0"
        rpy="0 0 0" />
      <geometry>
        <mesh
          filename="package://LR Mate-200iD7LC_v3/meshes/link_2.stl" />
      </geometry>
    </collision>
  </link>
  <joint
    name="joint_3"
    type="revolute">
    <origin
      xyz="0 -0.44 0.001"
      rpy="0 0 -1.5708" />
    <parent
      link="link_2" />
    <child
      link="link_3" />
    <axis
      xyz="0 0 -1" />
    <limit
      effort="0"
      velocity="0" />
  </joint>
  <link
    name="link_3">
    <inertial>
      <origin
        xyz="0.017646 0.0082385 0.00068041"
        rpy="0 0 0" />
      <mass
        value="2.3943E-10" />
      <inertia
        ixx="7.2607E-13"
        ixy="-7.6136E-14"
        ixz="-6.6486E-15"
        iyy="6.3347E-13"
        iyz="-4.9519E-15"
        izz="7.3283E-13" />
    </inertial>
    <visual>
      <origin
        xyz="0 0 0"
        rpy="0 0 0" />
      <geometry>
        <mesh
          filename="package://LR Mate-200iD7LC_v3/meshes/link_3.stl" />
      </geometry>
      <material
        name="material">
        <color
          rgba="1 1 1 1" />
      </material>
    </visual>
    <collision>
      <origin
        xyz="0 0 0"
        rpy="0 0 0" />
      <geometry>
        <mesh
          filename="package://LR Mate-200iD7LC_v3/meshes/link_3.stl" />
      </geometry>
    </collision>
  </link>
  <joint
    name="joint_4"
    type="revolute">
    <origin
      xyz="0.035055 0.0885 0.0034374"
      rpy="-1.5708 0 0" />
    <parent
      link="link_3" />
    <child
      link="link_4" />
    <axis
      xyz="0 0 1" />
    <limit
      effort="0"
      velocity="0" />
  </joint>
  <link
    name="link_4">
    <inertial>
      <origin
        xyz="0.000280639031589258 -0.00151675372081922 0.150025318560291"
        rpy="0 0 0" />
      <mass
        value="2.89083663942788E-10" />
      <inertia
        ixx="2.7118710726577E-12"
        ixy="-4.22692034629201E-16"
        ixz="6.33470383165278E-16"
        iyy="2.66766193936215E-12"
        iyz="2.43754531024021E-14"
        izz="4.81639781331482E-13" />
    </inertial>
    <visual>
      <origin
        xyz="0 0 0"
        rpy="0 0 0" />
      <geometry>
        <mesh
          filename="package://LR Mate-200iD7LC_v3/meshes/link_4.stl" />
      </geometry>
      <material
        name="material">
        <color
          rgba="1 1 1 1" />
      </material>
    </visual>
    <collision>
      <origin
        xyz="0 0 0"
        rpy="0 0 0" />
      <geometry>
        <mesh
          filename="package://LR Mate-200iD7LC_v3/meshes/link_4.stl" />
      </geometry>
    </collision>
  </link>
  <joint
    name="joint_5"
    type="revolute">
    <origin
      xyz="0 0.00325000014011412 0.3299"
      rpy="1.5707963267949 0 0" />
    <parent
      link="link_4" />
    <child
      link="link_5" />
    <axis
      xyz="0 0 -1" />
  </joint>
  <link
    name="link_5">
    <inertial>
      <origin
        xyz="-5.39703910817924E-05 0.0228858480520514 0.00271401908400257"
        rpy="0 0 0" />
      <mass
        value="4.90676836932377E-11" />
      <inertia
        ixx="7.39582979615282E-14"
        ixy="-2.21382710757271E-17"
        ixz="1.53281929800326E-18"
        iyy="3.33251646308528E-14"
        iyz="3.48694876332738E-15"
        izz="7.62756055864461E-14" />
    </inertial>
    <visual>
      <origin
        xyz="0 0 0"
        rpy="0 0 0" />
      <geometry>
        <mesh
          filename="package://LR Mate-200iD7LC_v3/meshes/link_5.stl" />
      </geometry>
      <material
        name="material">
        <color
          rgba="0.792156862745098 0.819607843137255 0.933333333333333 1" />
      </material>
    </visual>
    <collision>
      <origin
        xyz="0 0 0"
        rpy="0 0 0" />
      <geometry>
        <mesh
          filename="package://LR Mate-200iD7LC_v3/meshes/link_5.stl" />
      </geometry>
    </collision>
  </link>
  <joint
    name="joint_6"
    type="revolute">
    <origin
      xyz="0 0.092 0"
      rpy="-1.5707963267949 0 -1.52655665885959E-16" />
    <parent
      link="link_5" />
    <child
      link="link_6" />
    <axis
      xyz="0 0 1" />
  </joint>
  <link
    name="link_6">
    <inertial>
      <origin
        xyz="-0.000357123453930908 -2.19615992058664E-15 -0.00301527700965942"
        rpy="0 0 0" />
      <mass
        value="0.00519569112754826" />
      <inertia
        ixx="6.79263570772596E-07"
        ixy="-8.07888787912594E-23"
        ixz="2.83465397135916E-11"
        iyy="6.49376752288784E-07"
        iyz="1.86631228139104E-22"
        izz="1.29765869590308E-06" />
    </inertial>
    <visual>
      <origin
        xyz="0 0 0"
        rpy="0 0 0" />
      <geometry>
        <mesh
          filename="package://LR Mate-200iD7LC_v3/meshes/link_6.stl" />
      </geometry>
      <material
        name="material">
        <color
          rgba="0.792156862745098 0.819607843137255 0.933333333333333 1" />
      </material>
    </visual>
    <collision>
      <origin
        xyz="0 0 0"
        rpy="0 0 0" />
      <geometry>
        <mesh
          filename="package://LR Mate-200iD7LC_v3/meshes/link_6.stl" />
      </geometry>
    </collision>
  </link>
  <joint name="tool0" type="fixed">
    <origin rpy="0 0 3.14159265359" xyz="0 0.0298709 0.2022645"/>
    <parent link="link_6"/>
    <child link="spatula"/>
    <axis
      xyz="0 0 1" />
  </joint>
  <!-- ROS base_link to Fanuc World Coordinates transform -->
  <link name="spatula">
    <inertial>
      <origin rpy="0 0 0" xyz="0.0099352 -2.1879000003779E-08 -0.061718"/>
      <mass value="0.24255"/>
      <inertia ixx="0.00113499589370844" ixy="6.99518612221559E-10" ixz="-0.000160957555056342" iyy="0.0010816844051297" iyz="-1.37710136366572E-10" izz="0.000142854940329239"/>
    </inertial>
    <visual>
      <origin rpy="1.57079632679 0 0" xyz="0 0 0"/>
      <geometry>
        <mesh filename="package://miso_description/meshes/pilot_spatula-1.0-fine.stl"/>
      </geometry>
      <material name="">
        <color rgba="0.77647 0.75686 0.73725 1"/>
      </material>
    </visual>
    <collision>
      <origin rpy="1.57079632679 0 0" xyz="0 0 0"/>
      <geometry>
        <mesh filename="package://miso_description/meshes/pilot_spatula-1.0-coarse.stl"/>
      </geometry>
    </collision>
  </link>
  <transmission name="shoulder_pan_trans">
  	<type>transmission_interface/SimpleTransmission</type>
	<joint name="joint_1">
		<hardwareInterface>PositionJointInterface</hardwareInterface>
	</joint>
	<actuator name="shoulder_pan_motor">
	<mechanicalReduction>1</mechanicalReduction>
	</actuator>
  </transmission>
  <transmission name="shoulder_lift_trans">
	<type>transmission_interface/SimpleTransmission</type>
	<joint name="joint_2">
		<hardwareInterface>PositionJointInterface</hardwareInterface>
	</joint>
	<actuator name="shoulder_lift_motor">
	<mechanicalReduction>1</mechanicalReduction>
	</actuator>
  </transmission>
  <transmission name="elbow_trans">
	<type>transmission_interface/SimpleTransmission</type>
	<joint name="joint_3">
		<hardwareInterface>PositionJointInterface</hardwareInterface>
	</joint>
	<actuator name="elbow_motor">
	<mechanicalReduction>1</mechanicalReduction>
	</actuator>
  </transmission>
  <transmission name="wrist_1_trans">
	<type>transmission_interface/SimpleTransmission</type>
	<joint name="joint_4">
		<hardwareInterface>PositionJointInterface</hardwareInterface>
	</joint>
	<actuator name="wrist_1_motor">
	<mechanicalReduction>1</mechanicalReduction>
	</actuator>
  </transmission>
  <transmission name="wrist_2_trans">
	<type>transmission_interface/SimpleTransmission</type>
	<joint name="joint_5">
	<hardwareInterface>PositionJointInterface</hardwareInterface>
	</joint>
	<actuator name="wrist_2_motor">
	<mechanicalReduction>1</mechanicalReduction>
	</actuator>
  </transmission>
  <transmission name="wrist_3_trans">
	<type>transmission_interface/SimpleTransmission</type>
	<joint name="joint_6">
		<hardwareInterface>PositionJointInterface</hardwareInterface>
	</joint>
	<actuator name="wrist_3_motor">
	<mechanicalReduction>1</mechanicalReduction>
	</actuator></transmission>
</robot>
