<?xml version="1.0" ?>
<!-- =================================================================================== -->
<!-- |    This document was autogenerated by xacro from atrias.xacro                   | -->
<!-- |    EDITING THIS FILE BY HAND IS NOT RECOMMENDED                                 | -->
<!-- =================================================================================== -->
<!-- Author: Ross Hartley
Date:   1/16/2016   -->
<robot name="atrias" xmlns:xacro="http://ros.org/wiki/xacro">
  <link name="torso">
    <inertial>
      <origin rpy="0 0 0" xyz="0 -0.0018 0.4024"/>
      <mass value="21.5"/>
      <inertia ixx="2.0437" ixy="0" ixz="0" iyy="1.5226" iyz="0" izz="0.9154"/>
    </inertial>
    <visual>
      <origin rpy="1.57079632679 0 1.57079632679" xyz="0.225 0 .3"/>
      <geometry>
        <mesh filename="package://atrias_description/meshes/torso.stl" scale="1 1 1"/>
      </geometry>
      <material name="grey">
        <color rgba="0.4 0.4 0.4 1"/>
      </material>
    </visual>
  </link>
  <link name="hipRight">
    <inertial>
      <origin rpy="0 0 0" xyz="0.1834 0.00025 0.00678"/>
      <mass value="12.84085"/>
      <inertia ixx="0.10791" ixy="-0.00489" ixz="-0.01393" iyy="0.11101" iyz="0.0030" izz="0.06896"/>
    </inertial>
    <visual>
      <origin rpy="1.57079632679 0 1.57079632679" xyz="0 0 0"/>
      <geometry>
        <mesh filename="package://atrias_description/meshes/hip_shaft.stl" scale="1 1 1"/>
      </geometry>
      <material name="orange">
        <color rgba="0.9568 0.4784 0.2588 1"/>
      </material>
    </visual>
  </link>
  <link name="shinRight">
    <inertial>
      <origin rpy="0 0 0" xyz="-0.0045 -0.0157 0.1822"/>
      <mass value="0.7555"/>
      <inertia ixx="0.0309" ixy="0" ixz="0.0004" iyy="0.0295" iyz="0.0006" izz="0.0024"/>
    </inertial>
    <visual>
      <origin rpy="1.57079632679 3.14159 1.57079632679" xyz="0 0 0"/>
      <geometry>
        <mesh filename="package://atrias_description/meshes/shin.stl" scale="1 1 1"/>
      </geometry>
      <material name="grey">
        <color rgba="0.4 0.4 0.4 1"/>
      </material>
    </visual>
  </link>
  <link name="thighRight">
    <inertial>
      <origin rpy="0 0 0" xyz="0.0062 0.0253 0.1435"/>
      <mass value="0.7671"/>
      <inertia ixx="0.0228" ixy="0.0001" ixz="-0.0004" iyy="0.0210" iyz="-0.0014" izz="0.0029"/>
    </inertial>
    <visual>
      <origin rpy="1.57079632679 3.14159 1.57079632679" xyz="0 0 0"/>
      <geometry>
        <mesh filename="package://atrias_description/meshes/thigh.stl" scale="1 1 1"/>
      </geometry>
      <material name="grey">
        <color rgba="0.4 0.4 0.4 1"/>
      </material>
    </visual>
  </link>
  <link name="fourBarLinkRight">
    <inertial>
      <origin rpy="0 0 0" xyz="0.0 0.0014 0.1137"/>
      <mass value="0.6460"/>
      <inertia ixx="0.0176" ixy="0" ixz="0" iyy="0.0179" iyz="-0.0001" izz="0.0005"/>
    </inertial>
    <visual>
      <origin rpy="1.57079632679 3.14159 1.57079632679" xyz="0 0 0"/>
      <geometry>
        <mesh filename="package://atrias_description/meshes/lower_leg_two_point.stl" scale="1 1 1"/>
      </geometry>
      <material name="grey">
        <color rgba="0.4 0.4 0.4 1"/>
      </material>
    </visual>
  </link>
  <link name="lowerLegRight">
    <inertial>
      <origin rpy="0 0 0" xyz="2e-05 0.00017 0.15203"/>
      <mass value="0.39465"/>
      <inertia ixx="0.01260" ixy="0" ixz="0" iyy="0.01272" iyz="0" izz="0.00019"/>
    </inertial>
    <visual>
      <origin rpy="1.57079632679 3.14159 1.57079632679" xyz="0 0 0"/>
      <geometry>
        <mesh filename="package://atrias_description/meshes/lower_leg.stl" scale="1 1 1"/>
      </geometry>
      <material name="grey">
        <color rgba="0.4 0.4 0.4 1"/>
      </material>
    </visual>
  </link>
  <link name="hipLeft">
    <inertial>
      <origin rpy="0 0 0" xyz="-0.1834 0.00025 0.00678"/>
      <mass value="12.84085"/>
      <inertia ixx="0.10791" ixy="-0.00489" ixz="-0.01393" iyy="0.11101" iyz="0.0030" izz="0.06896"/>
    </inertial>
    <visual>
      <origin rpy="1.57079632679 0 -1.57079632679" xyz="0 0 0"/>
      <geometry>
        <mesh filename="package://atrias_description/meshes/hip_shaft.stl" scale="1 1 1"/>
      </geometry>
      <material name="orange">
        <color rgba="0.9568 0.4784 0.2588 1"/>
      </material>
    </visual>
  </link>
  <link name="shinLeft">
    <inertial>
      <origin rpy="0 0 0" xyz="0.0045 -0.0157 0.1822"/>
      <mass value="0.7555"/>
      <inertia ixx="0.0309" ixy="0" ixz="0.0004" iyy="0.0295" iyz="0.0006" izz="0.0024"/>
    </inertial>
    <visual>
      <origin rpy="1.57079632679 3.14159 1.57079632679" xyz="0 0 0"/>
      <geometry>
        <mesh filename="package://atrias_description/meshes/shin.stl" scale="1 1 1"/>
      </geometry>
      <material name="grey">
        <color rgba="0.4 0.4 0.4 1"/>
      </material>
    </visual>
  </link>
  <link name="thighLeft">
    <inertial>
      <origin rpy="0 0 0" xyz="-0.0062 0.0253 0.1435"/>
      <mass value="0.7671"/>
      <inertia ixx="0.0228" ixy="0.0001" ixz="-0.0004" iyy="0.0210" iyz="-0.0014" izz="0.0029"/>
    </inertial>
    <visual>
      <origin rpy="1.57079632679 3.14159 1.57079632679" xyz="0 0 0"/>
      <geometry>
        <mesh filename="package://atrias_description/meshes/thigh.stl" scale="1 1 1"/>
      </geometry>
      <material name="grey">
        <color rgba="0.4 0.4 0.4 1"/>
      </material>
    </visual>
  </link>
  <link name="fourBarLinkLeft">
    <inertial>
      <origin rpy="0 0 0" xyz="-0.0 0.0014 0.1137"/>
      <mass value="0.6460"/>
      <inertia ixx="0.0176" ixy="0" ixz="0" iyy="0.0179" iyz="-0.0001" izz="0.0005"/>
    </inertial>
    <visual>
      <origin rpy="1.57079632679 3.14159 1.57079632679" xyz="0 0 0"/>
      <geometry>
        <mesh filename="package://atrias_description/meshes/lower_leg_two_point.stl" scale="1 1 1"/>
      </geometry>
      <material name="grey">
        <color rgba="0.4 0.4 0.4 1"/>
      </material>
    </visual>
  </link>
  <link name="lowerLegLeft">
    <inertial>
      <origin rpy="0 0 0" xyz="-2e-05 0.00017 0.15203"/>
      <mass value="0.39465"/>
      <inertia ixx="0.01260" ixy="0" ixz="0" iyy="0.01272" iyz="0" izz="0.00019"/>
    </inertial>
    <visual>
      <origin rpy="1.57079632679 3.14159 1.57079632679" xyz="0 0 0"/>
      <geometry>
        <mesh filename="package://atrias_description/meshes/lower_leg.stl" scale="1 1 1"/>
      </geometry>
      <material name="grey">
        <color rgba="0.4 0.4 0.4 1"/>
      </material>
    </visual>
  </link>
  <joint name="qHRight" type="continuous">
    <origin rpy="0 0 0" xyz="0 0 0"/>
    <axis xyz="0 1 0"/>
    <parent link="torso"/>
    <child link="hipRight"/>
    <limit effort="3" lower="-0.3" upper="0.3" velocity="20"/>
  </joint>
  <joint name="qARight" type="continuous">
    <origin rpy="0 0 0" xyz="0.1831 0 0"/>
    <axis xyz="1 0 0"/>
    <parent link="hipRight"/>
    <child link="shinRight"/>
    <limit effort="5" lower="2" upper="5" velocity="20"/>
  </joint>
  <joint name="qBRight" type="continuous">
    <origin rpy="0 0 0" xyz="0.1831 0 0"/>
    <axis xyz="1 0 0"/>
    <parent link="hipRight"/>
    <child link="thighRight"/>
    <limit effort="5" lower="2" upper="5" velocity="20"/>
  </joint>
  <joint name="fourBarARight" type="continuous">
    <origin rpy="0 0 0" xyz="0 0 0.4"/>
    <axis xyz="1 0 0"/>
    <parent link="shinRight"/>
    <child link="fourBarLinkRight"/>
    <limit effort="0" lower="-10" upper="10" velocity="20"/>
  </joint>
  <joint name="fourBarBRight" type="continuous">
    <origin rpy="0 0 0" xyz="0 0 0.5"/>
    <axis xyz="1 0 0"/>
    <parent link="thighRight"/>
    <child link="lowerLegRight"/>
    <limit effort="0" lower="-10" upper="10" velocity="20"/>
  </joint>
  <joint name="qHLeft" type="continuous">
    <origin rpy="0 0 0" xyz="0 0 0"/>
    <axis xyz="0 1 0"/>
    <parent link="torso"/>
    <child link="hipLeft"/>
    <limit effort="3" lower="-0.3" upper="0.3" velocity="20"/>
  </joint>
  <joint name="qALeft" type="continuous">
    <origin rpy="0 0 0" xyz="-0.1831 0 0"/>
    <axis xyz="1 0 0"/>
    <parent link="hipLeft"/>
    <child link="shinLeft"/>
    <limit effort="5" lower="2" upper="5" velocity="20"/>
  </joint>
  <joint name="qBLeft" type="continuous">
    <origin rpy="0 0 0" xyz="-0.1831 0 0"/>
    <axis xyz="1 0 0"/>
    <parent link="hipLeft"/>
    <child link="thighLeft"/>
    <limit effort="5" lower="2" upper="5" velocity="20"/>
  </joint>
  <joint name="fourBarALeft" type="continuous">
    <origin rpy="0 0 0" xyz="0 0 0.4"/>
    <axis xyz="1 0 0"/>
    <parent link="shinLeft"/>
    <child link="fourBarLinkLeft"/>
    <limit effort="0" lower="-10" upper="10" velocity="20"/>
  </joint>
  <joint name="fourBarBLeft" type="continuous">
    <origin rpy="0 0 0" xyz="0 0 0.5"/>
    <axis xyz="1 0 0"/>
    <parent link="thighLeft"/>
    <child link="lowerLegLeft"/>
    <limit effort="0" lower="-10" upper="10" velocity="20"/>
  </joint>
  <transmission name="qH_trans_Right" type="transmission_interface/SimpleTransmission">
    <joint name="qHRight"/>
    <actuator name="qH_motor_Right"/>
    <mechanicalReduction>26.7</mechanicalReduction>
    <motorInertia>0.00070</motorInertia>
  </transmission>
  <transmission name="qA_trans_Right" type="transmission_interface/SimpleTransmission">
    <joint name="qARight"/>
    <actuator name="qA_motor_Right"/>
    <mechanicalReduction>50</mechanicalReduction>
    <motorInertia>0.00096</motorInertia>
  </transmission>
  <transmission name="qB_trans_Right" type="transmission_interface/SimpleTransmission">
    <joint name="qBRight"/>
    <actuator name="qB_motor_Right"/>
    <mechanicalReduction>50</mechanicalReduction>
    <motorInertia>0.00096</motorInertia>
  </transmission>
  <transmission name="qH_trans_Left" type="transmission_interface/SimpleTransmission">
    <joint name="qHLeft"/>
    <actuator name="qH_motor_Left"/>
    <mechanicalReduction>26.7</mechanicalReduction>
    <motorInertia>0.00070</motorInertia>
  </transmission>
  <transmission name="qA_trans_Left" type="transmission_interface/SimpleTransmission">
    <joint name="qALeft"/>
    <actuator name="qA_motor_Left"/>
    <mechanicalReduction>50</mechanicalReduction>
    <motorInertia>0.00096</motorInertia>
  </transmission>
  <transmission name="qB_trans_Left" type="transmission_interface/SimpleTransmission">
    <joint name="qBLeft"/>
    <actuator name="qB_motor_Left"/>
    <mechanicalReduction>50</mechanicalReduction>
    <motorInertia>0.00096</motorInertia>
  </transmission>
</robot>

