<?xml version="1.0" ?>
<!-- =================================================================================== -->
<!-- |    This document was autogenerated by xacro from five_link_walker.xacro         | -->
<!-- |    EDITING THIS FILE BY HAND IS NOT RECOMMENDED                                 | -->
<!-- =================================================================================== -->
<robot name="five_link_walker" xmlns:xacro="http://ros.org/wiki/xacro">
  <link name="torso">
    <inertial>
      <origin xyz="0 0 0.24" rpy="0 0 0"/>
      <mass value="12"/>
      <inertia ixx="0" ixy="0" ixz="0" iyy="1.33" iyz="0" izz="0"/>
    </inertial>
    <visual>
      <origin xyz="0 0 0.315"/>
      <geometry>
        <cylinder length="0.63" radius="0.025"/>
      </geometry>
      <material name="black">
        <color rgba="0 0 0 1"/>
      </material>
    </visual>
  </link>
  <link name="right_thigh">
    <inertial>
      <origin xyz="0 0 0.11" rpy="0 0 0"/>
      <mass value="6.8"/>
      <inertia ixx="0" ixy="0" ixz="0" iyy="0.47" iyz="0" izz="0"/>
    </inertial>
    <visual>
      <origin xyz="0 0 0.2"/>
      <geometry>
        <cylinder length="0.4" radius="0.025"/>
      </geometry>
      <material name="blue">
        <color rgba="0 0 1 1"/>
      </material>
    </visual>
  </link>
  <link name="left_thigh">
    <inertial>
      <origin xyz="0 0 0.11" rpy="0 0 0"/>
      <mass value="6.8"/>
      <inertia ixx="0" ixy="0" ixz="0" iyy="0.47" iyz="0" izz="0"/>
    </inertial>
    <visual>
      <origin xyz="0 0 0.2"/>
      <geometry>
        <cylinder length="0.4" radius="0.025"/>
      </geometry>
      <material name="red">
        <color rgba="1 0 0 1"/>
      </material>
    </visual>
  </link>
  <link name="right_shin">
    <inertial>
      <origin xyz="0 0 0.24" rpy="0 0 0"/>
      <mass value="3.2"/>
      <inertia ixx="0" ixy="0" ixz="0" iyy="0.2" iyz="0" izz="0"/>
    </inertial>
    <visual>
      <origin xyz="0 0 0.2"/>
      <geometry>
        <cylinder length="0.4" radius="0.025"/>
      </geometry>
      <material name="blue">
        <color rgba="1 0 0 1"/>
      </material>
    </visual>
  </link>
  <link name="left_shin">
    <inertial>
      <origin xyz="0 0 0.24" rpy="0 0 0"/>
      <mass value="3.2"/>
      <inertia ixx="0" ixy="0" ixz="0" iyy="0.2" iyz="0" izz="0"/>
    </inertial>
    <visual>
      <origin xyz="0 0 0.2"/>
      <geometry>
        <cylinder length="0.4" radius="0.025"/>
      </geometry>
      <material name="red">
        <color rgba="0 0 1 1"/>
      </material>
    </visual>
  </link>

  <joint name="q1_right" type="continuous">
    <origin xyz="0 0 0" rpy="0 0 0"/>
    <axis xyz="0 1 0"/>
    <parent link="torso"/>
    <child link="right_thigh"/>
  </joint>
   <joint name="q2_right" type="continuous">
    <origin xyz="0 0 0.4" rpy="0 0 0"/>
    <axis xyz="0 1 0"/>
    <parent link="right_thigh"/>
    <child link="right_shin"/>
  </joint>
    <joint name="q1_left" type="continuous">
    <origin xyz="0 0 0" rpy="0 0 0"/>
    <axis xyz="0 1 0"/>
    <parent link="torso"/>
    <child link="left_thigh"/>
  </joint>
  <joint name="q2_left" type="continuous">
    <origin xyz="0 0 0.4" rpy="0 0 0"/>
    <axis xyz="0 1 0"/>
    <parent link="left_thigh"/>
    <child link="left_shin"/>
  </joint>
  
  
<transmission name="q1_right_trans" type="pr2_mechanism_model/SimpleTransmission">
	<joint name="q1_right"/>
	<actuator name="q1_right_motor"/>
	<mechanicalReduction>50</mechanicalReduction>
    <motorInertia>0.000332</motorInertia>
</transmission>

<transmission name="q2_right_trans" type="pr2_mechanism_model/SimpleTransmission">
	<joint name="q2_right"/>
	<actuator name="q2_right_motor"/>
	<mechanicalReduction>50</mechanicalReduction>
    <motorInertia>0.000332</motorInertia>
</transmission>

<transmission name="q1_left_trans" type="pr2_mechanism_model/SimpleTransmission">
	<joint name="q1_left"/>
	<actuator name="q1_left_motor"/>
	<mechanicalReduction>50</mechanicalReduction>
    <motorInertia>0.000332</motorInertia>
</transmission>

<transmission name="q2_left_trans" type="pr2_mechanism_model/SimpleTransmission">
	<joint name="q2_left"/>
	<actuator name="q2_left_motor"/>
	<mechanicalReduction>50</mechanicalReduction>
    <motorInertia>0.000332</motorInertia>
</transmission>

</robot>
