<?xml version="1.0"?>
<robot name="durus_model">
  <link name="BaseRotZLink">
    <inertial>
      <origin xyz="0.01107 -0.00019 0.12791"/>
      <mass value="4.13245"/>
      <inertia ixx="0.0281" ixy="-1e-05" ixz="-8e-05" iyy="0.00956" iyz="3e-05" izz="0.03139"/>
    </inertial>
    <visual>
      <geometry>
        <mesh filename="package://durus_model/meshes/sym/BaseRotZ.stl"/>
      </geometry>
      <material name="">
        <color rgba="0.75 0.75 0.75 1.0"/>
      </material>
    </visual>
    <collision>
      <geometry>
        <mesh filename="package://durus_model/meshes/sym/BaseRotZ.stl"/>
      </geometry>
    </collision>
  </link>
  <joint name="WaistYaw" type="revolute">
    <origin xyz="0.0 0.0 0.2295" rpy="0.0 -0.0 0.0"/>
    <axis xyz="0 0 1"/>
    <parent link="BaseRotZLink"/>
    <child link="WaistYawLink"/>
    <limit effort="400.0" lower="-1.57079632679" upper="1.57079632679" velocity="10.0"/>
  </joint>
  <link name="WaistYawLink">
    <inertial>
      <origin xyz="-0.00812 -6e-05 -0.04716"/>
      <mass value="0.93834"/>
      <inertia ixx="0.0012" ixy="0.0" ixz="-0.00033" iyy="0.00182" iyz="0.0" izz="0.00164"/>
    </inertial>
    <visual>
      <geometry>
        <mesh filename="package://durus_model/meshes/sym/WaistYaw.stl"/>
      </geometry>
      <material name="">
        <color rgba="0.75 0.75 0.75 1.0"/>
      </material>
    </visual>
    <collision>
      <geometry>
        <mesh filename="package://durus_model/meshes/sym/WaistYaw.stl"/>
      </geometry>
    </collision>
  </link>
  <joint name="WaistRoll" type="revolute">
    <origin xyz="0.0 0.0 0.0" rpy="-3.14159265359 -1.57079632679 0.0"/>
    <axis xyz="0 0 1"/>
    <parent link="WaistYawLink"/>
    <child link="WaistRollLink"/>
    <limit effort="400.0" lower="-0.785398163397" upper="0.785398163397" velocity="10.0"/>
  </joint>
  <link name="WaistRollLink">
    <inertial>
      <origin xyz="0.0 0.0 0.0"/>
      <mass value="0.12018"/>
      <inertia ixx="0.00016" ixy="0.0" ixz="0.0" iyy="5e-05" iyz="0.0" izz="0.00012"/>
    </inertial>
    <visual>
      <geometry>
        <mesh filename="package://durus_model/meshes/sym/WaistRoll.stl"/>
      </geometry>
      <material name="">
        <color rgba="0.75 0.75 0.75 1.0"/>
      </material>
    </visual>
    <collision>
      <geometry>
        <mesh filename="package://durus_model/meshes/sym/WaistRoll.stl"/>
      </geometry>
    </collision>
  </link>
  <joint name="WaistPitch" type="revolute">
    <origin xyz="0.0 0.0 0.0" rpy="-1.57079632679 -0.0 0.0"/>
    <axis xyz="0 0 -1"/>
    <parent link="WaistRollLink"/>
    <child link="WaistPitchLink"/>
    <limit effort="400.0" lower="-0.785398163397" upper="0.785398163397" velocity="10.0"/>
  </joint>
  <link name="WaistPitchLink">
    <inertial>
      <origin xyz="0.20457 0.07861 0.00144"/>
      <mass value="30.14264"/>
      <inertia ixx="0.61755" ixy="-0.00573" ixz="-0.00106" iyy="0.55056" iyz="0.01271" izz="0.48475"/>
    </inertial>
    <visual>
      <geometry>
        <mesh filename="package://durus_model/meshes/sym/WaistPitch.stl"/>
      </geometry>
      <material name="">
        <color rgba="0.75 0.75 0.75 1.0"/>
      </material>
    </visual>
    <collision>
      <geometry>
        <mesh filename="package://durus_model/meshes/sym/WaistPitch.stl"/>
      </geometry>
    </collision>
  </link>
  <joint name="LeftHipYaw" type="revolute">
    <origin xyz="0.0 0.093 0.0" rpy="0.0 -0.0 0.0"/>
    <axis xyz="0 0 1"/>
    <parent link="BaseRotZLink"/>
    <child link="LeftHipYawLink"/>
    <limit effort="400.0" lower="-0.523598775598" upper="0.523598775598" velocity="10.0"/>
  </joint>
  <link name="LeftHipYawLink">
    <inertial>
      <origin xyz="0.00234 -0.0153 -0.0263"/>
      <mass value="3.60581"/>
      <inertia ixx="0.02313" ixy="-0.00054" ixz="-0.00121" iyy="0.02175" iyz="0.00391" izz="0.00604"/>
    </inertial>
    <visual>
      <geometry>
        <mesh filename="package://durus_model/meshes/sym/LeftHipYaw.stl"/>
      </geometry>
      <material name="">
        <color rgba="0.75 0.75 0.75 1.0"/>
      </material>
    </visual>
    <collision>
      <geometry>
        <mesh filename="package://durus_model/meshes/sym/LeftHipYaw.stl"/>
      </geometry>
    </collision>
  </link>
  <joint name="LeftHipRoll" type="revolute">
    <origin xyz="0.0 0.0 0.0" rpy="1.57079632679 -0.0 1.57079632679"/>
    <axis xyz="0 0 1"/>
    <parent link="LeftHipYawLink"/>
    <child link="LeftHipRollLink"/>
    <limit effort="450.0" lower="-0.349065850399" upper="1.0471975512" velocity="10.0"/>
  </joint>
  <link name="LeftHipRollLink">
    <inertial>
      <origin xyz="0.05192 -0.02256 -0.00467"/>
      <mass value="2.98347"/>
      <inertia ixx="0.00568" ixy="-0.00345" ixz="0.00068" iyy="0.01185" iyz="-0.00027" izz="0.01384"/>
    </inertial>
    <visual>
      <geometry>
        <mesh filename="package://durus_model/meshes/sym/LeftHipRoll.stl"/>
      </geometry>
      <material name="">
        <color rgba="0.75 0.75 0.75 1.0"/>
      </material>
    </visual>
    <collision>
      <geometry>
        <mesh filename="package://durus_model/meshes/sym/LeftHipRoll.stl"/>
      </geometry>
    </collision>
  </link>
  <joint name="LeftHipPitch" type="revolute">
    <origin xyz="0.0148 -0.045 0.0" rpy="1.57079632679 -0.0 -1.57079632679"/>
    <axis xyz="0 0 -1"/>
    <parent link="LeftHipRollLink"/>
    <child link="LeftHipPitchLink"/>
    <limit effort="450.0" lower="-1.57079632679" upper="1.57079632679" velocity="10.0"/>
  </joint>
  <link name="LeftHipPitchLink">
    <inertial>
      <origin xyz="0.15096 0.00558 -0.019"/>
      <mass value="6.80204"/>
      <inertia ixx="0.02235" ixy="-0.00833" ixz="-0.02211" iyy="0.12999" iyz="0.00051" izz="0.13326"/>
    </inertial>
    <visual>
      <geometry>
        <mesh filename="package://durus_model/meshes/sym/LeftHipPitch.stl"/>
      </geometry>
      <material name="">
        <color rgba="0.75 0.75 0.75 1.0"/>
      </material>
    </visual>
    <collision>
      <geometry>
        <mesh filename="package://durus_model/meshes/sym/LeftHipPitch.stl"/>
      </geometry>
    </collision>
  </link>
  <joint name="LeftKneePitch" type="revolute">
    <origin xyz="0.37 0.0 0.0" rpy="0.0 -0.0 0.0"/>
    <axis xyz="0 0 -1"/>
    <parent link="LeftHipPitchLink"/>
    <child link="LeftKneePitchLink"/>
    <limit effort="450.0" lower="0.0" upper="3.14159265359" velocity="10.0"/>
  </joint>
  <link name="LeftKneePitchLink">
    <inertial>
      <origin xyz="0.1176 0.00365 -0.00025"/>
      <mass value="6.29377"/>
      <inertia ixx="0.01553" ixy="-0.00031" ixz="0.0052" iyy="0.06716" iyz="-5e-05" izz="0.0684"/>
    </inertial>
    <visual>
      <geometry>
        <mesh filename="package://durus_model/meshes/sym/LeftKneePitch.stl"/>
      </geometry>
      <material name="">
        <color rgba="0.75 0.75 0.75 1.0"/>
      </material>
    </visual>
    <collision>
      <geometry>
        <mesh filename="package://durus_model/meshes/sym/LeftKneePitch.stl"/>
      </geometry>
    </collision>
  </link>
  <joint name="LeftAnklePitch" type="revolute">
    <origin xyz="0.34 0.0 0.0" rpy="0.0 -0.0 0.0"/>
    <axis xyz="0 0 -1"/>
    <parent link="LeftKneePitchLink"/>
    <child link="LeftAnklePitchLink"/>
    <limit effort="400.0" lower="-1.57079632679" upper="1.57079632679" velocity="10.0"/>
  </joint>
  <link name="LeftAnklePitchLink">
    <inertial>
      <origin xyz="0.0 0.00209 0.0"/>
      <mass value="0.15469"/>
      <inertia ixx="0.00036" ixy="0.0" ixz="0.0" iyy="0.00031" iyz="0.0" izz="9e-05"/>
    </inertial>
    <visual>
      <geometry>
        <mesh filename="package://durus_model/meshes/sym/LeftAnklePitch.stl"/>
      </geometry>
      <material name="">
        <color rgba="0.75 0.75 0.75 1.0"/>
      </material>
    </visual>
    <collision>
      <geometry>
        <mesh filename="package://durus_model/meshes/sym/LeftAnklePitch.stl"/>
      </geometry>
    </collision>
  </link>
  <joint name="LeftAnkleRoll" type="revolute">
    <origin xyz="0.0 0.0 0.0" rpy="-1.57079632679 -0.0 0.0"/>
    <axis xyz="0 0 1"/>
    <parent link="LeftAnklePitchLink"/>
    <child link="LeftAnkleRollLink"/>
    <limit effort="400.0" lower="-0.523598775598" upper="1.0471975512" velocity="10.0"/>
  </joint>
  <link name="LeftAnkleRollLink">
    <inertial>
      <origin xyz="0.01912 0.0 -0.00229"/>
      <mass value="0.66819"/>
      <inertia ixx="0.00046" ixy="0.0" ixz="3e-05" iyy="0.00101" iyz="0.0" izz="0.00115"/>
    </inertial>
    <visual>
      <geometry>
        <mesh filename="package://durus_model/meshes/sym/LeftAnkleRoll.stl"/>
      </geometry>
      <material name="">
        <color rgba="0.75 0.75 0.75 1.0"/>
      </material>
    </visual>
    <collision>
      <geometry>
        <mesh filename="package://durus_model/meshes/sym/LeftAnkleRoll.stl"/>
      </geometry>
    </collision>
  </link>
  <joint name="LeftFootSpring" type="prismatic">
    <origin xyz="0.148 0.0 0.0" rpy="1.57079632679 -0.0 0.0"/>
    <axis xyz="-1 0 0"/>
    <parent link="LeftAnkleRollLink"/>
    <child link="LeftFootSpringLink"/>
    <limit effort="0.0" lower="-0.01" upper="0.05" velocity="2.0"/>
  </joint>
  <link name="LeftFootSpringLink">
    <inertial>
      <origin xyz="0.04583 0.03984 -0.00037"/>
      <mass value="1.97295"/>
      <inertia ixx="0.00957" ixy="-0.00008" ixz="0.0" iyy="0.00675" iyz="0.0001" izz="0.0131"/>
    </inertial>
    <visual>
      <geometry>
        <mesh filename="package://durus_model/meshes/sym/LeftFootSpring.stl"/>
      </geometry>
      <material name="">
        <color rgba="0.75 0.75 0.75 1.0"/>
      </material>
    </visual>
    <collision>
      <geometry>
        <mesh filename="package://durus_model/meshes/sym/LeftFootSpring.stl"/>
      </geometry>
    </collision>
  </link>
  <joint name="RightHipYaw" type="revolute">
    <origin xyz="0.0 -0.093 0.0" rpy="0.0 -0.0 0.0"/>
    <axis xyz="0 0 1"/>
    <parent link="BaseRotZLink"/>
    <child link="RightHipYawLink"/>
    <limit effort="400.0" lower="-0.523598775598" upper="0.523598775598" velocity="10.0"/>
  </joint>
  <link name="RightHipYawLink">
    <inertial>
      <origin xyz="0.00234 0.0153 -0.0263"/>
      <mass value="3.60581"/>
      <inertia ixx="0.02313" ixy="0.00054" ixz="-0.00121" iyy="0.02175" iyz="-0.00391" izz="0.00604"/>
    </inertial>
    <visual>
      <geometry>
        <mesh filename="package://durus_model/meshes/sym/RightHipYaw.stl"/>
      </geometry>
      <material name="">
        <color rgba="0.75 0.75 0.75 1.0"/>
      </material>
    </visual>
    <collision>
      <geometry>
        <mesh filename="package://durus_model/meshes/sym/RightHipYaw.stl"/>
      </geometry>
    </collision>
  </link>
  <joint name="RightHipRoll" type="revolute">
    <origin xyz="0.0 0.0 0.0" rpy="1.57079632679 -0.0 1.57079632679"/>
    <axis xyz="0 0 1"/>
    <parent link="RightHipYawLink"/>
    <child link="RightHipRollLink"/>
    <limit effort="450.0" lower="-1.0471975512" upper="0.349065850399" velocity="10.0"/>
  </joint>
  <link name="RightHipRollLink">
    <inertial>
      <origin xyz="-0.05192 -0.02256 -0.00467"/>
      <mass value="2.98347"/>
      <inertia ixx="0.00568" ixy="0.00345" ixz="-0.00068" iyy="0.01185" iyz="-0.00027" izz="0.01384"/>
    </inertial>
    <visual>
      <geometry>
        <mesh filename="package://durus_model/meshes/sym/RightHipRoll.stl"/>
      </geometry>
      <material name="">
        <color rgba="0.75 0.75 0.75 1.0"/>
      </material>
    </visual>
    <collision>
      <geometry>
        <mesh filename="package://durus_model/meshes/sym/RightHipRoll.stl"/>
      </geometry>
    </collision>
  </link>
  <joint name="RightHipPitch" type="revolute">
    <origin xyz="-0.0148 -0.045 0.0" rpy="1.57079632679 -0.0 -1.57079632679"/>
    <axis xyz="0 0 -1"/>
    <parent link="RightHipRollLink"/>
    <child link="RightHipPitchLink"/>
    <limit effort="450.0" lower="-1.57079632679" upper="1.57079632679" velocity="10.0"/>
  </joint>
  <link name="RightHipPitchLink">
    <inertial>
      <origin xyz="0.15096 0.00558 0.019"/>
      <mass value="6.80204"/>
      <inertia ixx="0.02235" ixy="-0.00833" ixz="0.02211" iyy="0.12999" iyz="-0.00051" izz="0.13326"/>
    </inertial>
    <visual>
      <geometry>
        <mesh filename="package://durus_model/meshes/sym/RightHipPitch.stl"/>
      </geometry>
      <material name="">
        <color rgba="0.75 0.75 0.75 1.0"/>
      </material>
    </visual>
    <collision>
      <geometry>
        <mesh filename="package://durus_model/meshes/sym/RightHipPitch.stl"/>
      </geometry>
    </collision>
  </link>
  <joint name="RightKneePitch" type="revolute">
    <origin xyz="0.37 0.0 0.0" rpy="0.0 -0.0 0.0"/>
    <axis xyz="0 0 -1"/>
    <parent link="RightHipPitchLink"/>
    <child link="RightKneePitchLink"/>
    <limit effort="450.0" lower="0.0" upper="3.14159265359" velocity="10.0"/>
  </joint>
  <link name="RightKneePitchLink">
    <inertial>
      <origin xyz="0.1176 0.00365 0.00025"/>
      <mass value="6.29377"/>
      <inertia ixx="0.01553" ixy="-0.00031" ixz="-0.0052" iyy="0.06716" iyz="5e-05" izz="0.0684"/>
    </inertial>
    <visual>
      <geometry>
        <mesh filename="package://durus_model/meshes/sym/RightKneePitch.stl"/>
      </geometry>
      <material name="">
        <color rgba="0.75 0.75 0.75 1.0"/>
      </material>
    </visual>
    <collision>
      <geometry>
        <mesh filename="package://durus_model/meshes/sym/RightKneePitch.stl"/>
      </geometry>
    </collision>
  </link>
  <joint name="RightAnklePitch" type="revolute">
    <origin xyz="0.34 0.0 0.0" rpy="0.0 -0.0 0.0"/>
    <axis xyz="0 0 -1"/>
    <parent link="RightKneePitchLink"/>
    <child link="RightAnklePitchLink"/>
    <limit effort="400.0" lower="-1.57079632679" upper="1.57079632679" velocity="10.0"/>
  </joint>
  <link name="RightAnklePitchLink">
    <inertial>
      <origin xyz="0.0 0.00209 0.0"/>
      <mass value="0.15469"/>
      <inertia ixx="0.00036" ixy="0.0" ixz="0.0" iyy="0.00031" iyz="0.0" izz="9e-05"/>
    </inertial>
    <visual>
      <geometry>
        <mesh filename="package://durus_model/meshes/sym/RightAnklePitch.stl"/>
      </geometry>
      <material name="">
        <color rgba="0.75 0.75 0.75 1.0"/>
      </material>
    </visual>
    <collision>
      <geometry>
        <mesh filename="package://durus_model/meshes/sym/RightAnklePitch.stl"/>
      </geometry>
    </collision>
  </link>
  <joint name="RightAnkleRoll" type="revolute">
    <origin xyz="0.0 0.0 0.0" rpy="-1.57079632679 -0.0 0.0"/>
    <axis xyz="0 0 1"/>
    <parent link="RightAnklePitchLink"/>
    <child link="RightAnkleRollLink"/>
    <limit effort="400.0" lower="-1.0471975512" upper="0.523598775598" velocity="10.0"/>
  </joint>
  <link name="RightAnkleRollLink">
    <inertial>
      <origin xyz="0.01912 0.0 -0.00229"/>
      <mass value="0.66819"/>
      <inertia ixx="0.00046" ixy="0.0" ixz="3e-05" iyy="0.00101" iyz="0.0" izz="0.00115"/>
    </inertial>
    <visual>
      <geometry>
        <mesh filename="package://durus_model/meshes/sym/RightAnkleRoll.stl"/>
      </geometry>
      <material name="">
        <color rgba="0.75 0.75 0.75 1.0"/>
      </material>
    </visual>
    <collision>
      <geometry>
        <mesh filename="package://durus_model/meshes/sym/RightAnkleRoll.stl"/>
      </geometry>
    </collision>
  </link>
  <joint name="RightFootSpring" type="prismatic">
    <origin xyz="0.148 0.0 0.0" rpy="1.57079632679 -0.0 0.0"/>
    <axis xyz="-1 0 0"/>
    <parent link="RightAnkleRollLink"/>
    <child link="RightFootSpringLink"/>
    <limit effort="0.0" lower="-0.01" upper="0.05" velocity="2.0"/>
  </joint>
  <link name="RightFootSpringLink">
    <inertial>
      <origin xyz="0.04583 0.03984 0.00037"/>
      <mass value="1.97295"/>
      <inertia ixx="0.00957" ixy="-0.00008" ixz="0.0" iyy="0.00675" iyz="-0.0001" izz="0.0131"/>
    </inertial>
    <visual>
      <geometry>
        <mesh filename="package://durus_model/meshes/sym/RightFootSpring.stl"/>
      </geometry>
      <material name="">
        <color rgba="0.75 0.75 0.75 1.0"/>
      </material>
    </visual>
    <collision>
      <geometry>
        <mesh filename="package://durus_model/meshes/sym/RightFootSpring.stl"/>
      </geometry>
    </collision>
  </link>
</robot>
